Workbook

Sheet Dataset
A1: Loan Dataset | F1: L = ICA
A3: Row | B3: Loan Amt (L) | C3: Income (I) | D3: Credit Score (C) | F3: Approval (%)
A4: 1 | B4: 10000 | C4: 45000 | D4: 720 | F4: 70
A5: 2 | B5: 15000 | C5: 60000 | D5: 680 | F5: 40
A6: 3 | B6: 85000 | C6: 85000 | D6: 750 | F6: 80
A7: 4 | B7: 12000 | C7: 50000 | D7: 690 | F7: 30
A8: 5 | B8: 25000 | C8: 100000 | D8: 800 | F8: 75
A9: Mean | B9: =AVERAGE(B4:B8) -> 29400 | C9: =AVERAGE(C4:C8) -> 68000 | D9: =AVERAGE(D4:D8) -> 728 | F9: =AVERAGE(F4:F8) -> 59
A11: Note: 'Mean' row = the background/reference point used to represent a 'missing' feature when computing Shapley values (a common choice when you only have a dataset, not a full simulator).

Sheet Model & Baseline
A1: Surrogate Black-Box Model f(x) — Linear Regression Stand-in | H1: Loan Dataset | M1: A(actual) Approval (%) = y | N1: A(hat)=y(hat)=>MODEL | P1: L = ICA
H2: Row | I2: L | J2: I | K2: C | P2: Loan | Q2: L
A3: Since we don't have the actual Random Forest / Neural Net, a linear model was fit to the 5 rows (least squares, via Python/scikit-learn) to act as f(x). Coefficients below are hardcoded inputs (documented) — everything downstream is a live formula. | H3: 1 | I3: 10000 | J3: 45000 | K3: 720 | M3: 0.7 | N3: =$B$5 + $B$6*I3 + $B$7*J3 + $B$8*K3 -> 63.613415 | P3: Income | Q3: I
H4: 2 | I4: 15000 | J4: 60000 | K4: 680 | M4: 0.4 | N4: =$B$5 + $B$6*I4 + $B$7*J4 + $B$8*K4 -> 31.827177 | P4: Credit Score | Q4: C
A5: Intercept (b0) | B5: -321.5839 | H5: 3 | I5: 85000 | J5: 85000 | K5: 750 | M5: 0.8 | N5: =$B$5 + $B$6*I5 + $B$7*J5 + $B$8*K5 -> 79.981197 | P5: Approval (%) | Q5: A
A6: Coef L (b1) | B6: 0.00036724268 | C6: Loan Amt (L) | H6: 4 | I6: 12000 | J6: 50000 | K6: 690 | M6: 0.3 | N6: =$B$5 + $B$6*I6 + $B$7*J6 + $B$8*K6 -> 43.569142
A7: Coef I (b2) | B7: -0.00071009283 | C7: Income (I) | H7: 5 | I7: 25000 | J7: 100000 | K7: 800 | M7: 0.75 | N7: =$B$5 + $B$6*I7 + $B$7*J7 + $B$8*K7 -> 76.009068
A8: Coef C (b3) | B8: 0.57427648 | C8: Credit Score (C) | H8: Mean | I8: =AVERAGE(I3:I7) -> 29400 | J8: =AVERAGE(J3:J7) -> 68000 | K8: =AVERAGE(K3:K7) -> 728 | M8: =AVERAGE(M3:M7) -> 0.59
I9: L | J9: I | K9: C
A10: Source: fit with sklearn.linear_model.LinearRegression() on the 5-row Loan Dataset (ordinary least squares). Predicts Approval (%) from L, I, C. | I10: X1(or L) | J10: X2 | K10: X3 | M10: Independent variables; Model(y) is dependeent variable or Target variable;
H11: Model(y) => | I11: b0 + b1*X1 + b2*X2 + b3*X3
A14: Model prediction formula: A= f(L,I,C) = b0 + b1*L + b2*I + b3*C
A15: Baseline v(∅) = f(mean L, mean I, mean C) | D15: =B5 + B6*Dataset!B9 + B7*Dataset!C9 + B8*Dataset!D9 -> 59
A17: when we take Mean values of (LIC) to get A(loan approval)= | D17: =B5 + B6* I8 + B7*J8 + B8* K8 -> 59

Sheet Row2 Brute-Force Detail
A1: Worked Example — Row 2 (L=$15,000, I=$60,000, C=680) — Full Shapley Enumeration | J1: Mean | K1: when someone is not participating => we give HIM (mean value as HIS share)!
J2: 29400
A3: This sheet brute-forces the exact Shapley formula: phi_i = sum over subsets S of others [ |S|!(n-|S|-1)!/n! * (v(S∪i) - v(S)) ], n=3 features, so 8 subsets total. | J3: 68000
J4: 728
A5: Instance to explain (Row 2):
D6: Row | E6: L | F6: I | G6: C
D7: 1 | E7: 10000 | F7: 45000 | G7: 720 | K7: Baseline+ sum(phi) | M7: Intercept (b0) | N7: -321.5839
D8: 2 | E8: 15000 | F8: 60000 | G8: 680 | H8: BY CLAUD | K8: 63.613415 | M8: Coef L (b1) | N8: 0.00036724268
A9: Step 1 — Value function v(S) for all 8 coalitions | K9: 31.827177 | M9: Coef I (b2) | N9: -0.00071009283
A10: Subset S | B10: L in S? | C10: I in S? | D10: C in S? | E10: L used | F10: I used | G10: C used | H10: v(S) = f(...) | I10: my_v(S) | K10: 79.981197 | M10: Coef C (b3) | N10: 0.57427648
A11: {} | B11: 0 | C11: 0 | D11: 0 | E11: =IF(B11=1,$E$8,Dataset!$B$9) -> 29400 | F11: =IF(C11=1,$F$8,Dataset!$C$9) -> 68000 | G11: =IF(D11=1,$G$8,Dataset!$D$9) -> 728 | H11: ='Model & Baseline'!$B$5 + 'Model & Baseline'!$B$6*E11 + 'Model & Baseline'!$B$7*F11 + 'Model & Baseline'!$B$8*G11 -> 59 | I11: =$N$7 + $N$8*E11 + $N$9*F11 + $N$10*G11 -> 59 | K11: 43.569142
A13: {L} | B13: 1 | C13: 0 | D13: 0 | E13: =IF(B13=1,$E$8, Dataset!$B$9) -> 15000 | F13: =IF(C13=1,$F$8, Dataset!$C$9) -> 68000 | G13: =IF(D13=1, $G$8, Dataset!$D$9) -> 728 | H13: ='Model & Baseline'!$B$5 + 'Model & Baseline'!$B$6*E13 + 'Model & Baseline'!$B$7*F13 + 'Model & Baseline'!$B$8*G13 -> 53.711705 | I13: =$N$7 + $N$8*E13 + $N$9*F13 + $N$10*G13 -> 53.711705 | K13: 76.009068
A14: {I} | B14: 0 | C14: 1 | D14: 0 | E14: =IF(B14=1,$E$8,Dataset!$B$9) -> 29400 | F14: =IF(C14=1,$F$8,Dataset!$C$9) -> 60000 | G14: =IF(D14=1,$G$8,Dataset!$D$9) -> 728 | H14: ='Model & Baseline'!$B$5 + 'Model & Baseline'!$B$6*E14 + 'Model & Baseline'!$B$7*F14 + 'Model & Baseline'!$B$8*G14 -> 64.680743 | I14: =$N$7 + $N$8*E14 + $N$9*F14 + $N$10*G14 -> 64.680743
A15: {C} | B15: 0 | C15: 0 | D15: 1 | E15: =IF(B15=1,$E$8,Dataset!$B$9) -> 29400 | F15: =IF(C15=1,$F$8,Dataset!$C$9) -> 68000 | G15: =IF(D15=1,$G$8,Dataset!$D$9) -> 680 | H15: ='Model & Baseline'!$B$5 + 'Model & Baseline'!$B$6*E15 + 'Model & Baseline'!$B$7*F15 + 'Model & Baseline'!$B$8*G15 -> 31.434729 | I15: =$N$7 + $N$8*E15 + $N$9*F15 + $N$10*G15 -> 31.434729
A16: {L,I} | B16: 1 | C16: 1 | D16: 0 | E16: =IF(B16=1,$E$8,Dataset!$B$9) -> 15000 | F16: =IF(C16=1,$F$8,Dataset!$C$9) -> 60000 | G16: =IF(D16=1,$G$8,Dataset!$D$9) -> 728 | H16: ='Model & Baseline'!$B$5 + 'Model & Baseline'!$B$6*E16 + 'Model & Baseline'!$B$7*F16 + 'Model & Baseline'!$B$8*G16 -> 59.392448 | I16: =$N$7 + $N$8*E16 + $N$9*F16 + $N$10*G16 -> 59.392448
A17: {L,C} | B17: 1 | C17: 0 | D17: 1 | E17: =IF(B17=1,$E$8,Dataset!$B$9) -> 15000 | F17: =IF(C17=1,$F$8,Dataset!$C$9) -> 68000 | G17: =IF(D17=1,$G$8,Dataset!$D$9) -> 680 | H17: ='Model & Baseline'!$B$5 + 'Model & Baseline'!$B$6*E17 + 'Model & Baseline'!$B$7*F17 + 'Model & Baseline'!$B$8*G17 -> 26.146434 | I17: =$N$7 + $N$8*E17 + $N$9*F17 + $N$10*G17 -> 26.146434 | Q17: A(hat) for Row_2
A18: {I,C} | B18: 0 | C18: 1 | D18: 1 | E18: =IF(B18=1,$E$8,Dataset!$B$9) -> 29400 | F18: =IF(C18=1,$F$8,Dataset!$C$9) -> 60000 | G18: =IF(D18=1,$G$8,Dataset!$D$9) -> 680 | H18: ='Model & Baseline'!$B$5 + 'Model & Baseline'!$B$6*E18 + 'Model & Baseline'!$B$7*F18 + 'Model & Baseline'!$B$8*G18 -> 37.115472 | I18: =$N$7 + $N$8*E18 + $N$9*F18 + $N$10*G18 -> 37.115472 | J18: Check: baseline + phi_L + phi_I + phi_C = | Q18: =P30 + H29 + H35 + H41 -> 31.827177
A19: {L,I,C} | B19: 1 | C19: 1 | D19: 1 | E19: =IF(B19=1,$E$8,Dataset!$B$9) -> 15000 | F19: =IF(C19=1,$F$8,Dataset!$C$9) -> 60000 | G19: =IF(D19=1,$G$8,Dataset!$D$9) -> 680 | H19: ='Model & Baseline'!$B$5 + 'Model & Baseline'!$B$6*E19 + 'Model & Baseline'!$B$7*F19 + 'Model & Baseline'!$B$8*G19 -> 31.827177 | I19: =$N$7 + $N$8*E19 + $N$9*F19 + $N$10*G19 -> 31.827177 | J19: Should equal model prediction f(15000,60000,680) = | Q19: =P26 -> 31.827177
A21: Baseline v(∅) = f(mean L, mean I, mean C) | D21: ='Model & Baseline'!M8 -> 0.59
A22: Step 2 — Weighted marginal contributions per feature (n=3, weights = |S|!(n-|S|-1)!/3!) | K22: Loan Dataset
A23: Feature | B23: Coalition S (others) | C23: |S| | D23: Weight | E23: v(S∪i) | F23: v(S) | G23: Marginal | H23: Weight × Marginal | K23: Row | L23: L | M23: I | N23: C | O23: A | P23: A(hat)
A24: phi_L =
A25: L | B25: {} (add to {}) | C25: 0 | D25: =FACT(C25)*FACT(3-C25-1)/FACT(3) -> 0.33333333 | E25: =H13 -> 53.711705 | F25: =H11 -> 59 | G25: =E25-F25 -> -5.2882946 | H25: =D25*G25 -> -1.7627649 | K25: 1 | L25: 10000 | M25: 45000 | N25: 720 | O25: 70 | P25: ='Model & Baseline'!N3 -> 63.613415
A26: L | B26: {I} (add to {I}) | C26: 1 | D26: =FACT(C26)*FACT(3-C26-1)/FACT(3) -> 0.16666667 | E26: =H16 -> 59.392448 | F26: =H14 -> 64.680743 | G26: =E26-F26 -> -5.2882946 | H26: =D26*G26 -> -0.88138244 | K26: 2 | L26: 15000 | M26: 60000 | N26: 680 | O26: 40 | P26: ='Model & Baseline'!N4 -> 31.827177
A27: L | B27: {C} (add to {C}) | C27: 1 | D27: =FACT(C27)*FACT(3-C27-1)/FACT(3) -> 0.16666667 | E27: =H17 -> 26.146434 | F27: =H15 -> 31.434729 | G27: =E27-F27 -> -5.2882946 | H27: =D27*G27 -> -0.88138244 | K27: 3 | L27: 85000 | M27: 85000 | N27: 750 | O27: 80 | P27: ='Model & Baseline'!N5 -> 79.981197
A28: L | B28: {I,C} (add to {I,C}) | C28: 2 | D28: =FACT(C28)*FACT(3-C28-1)/FACT(3) -> 0.33333333 | E28: =H19 -> 31.827177 | F28: =H18 -> 37.115472 | G28: =E28-F28 -> -5.2882946 | H28: =D28*G28 -> -1.7627649 | K28: 4 | L28: 12000 | M28: 50000 | N28: 690 | O28: 30 | P28: ='Model & Baseline'!N6 -> 43.569142
H29: =SUM(H25:H28) -> -5.2882946 | K29: 5 | L29: 25000 | M29: 100000 | N29: 800 | O29: 75 | P29: ='Model & Baseline'!N7 -> 76.009068
A30: phi_I = | K30: Mean | L30: =AVERAGE(L25:L29) -> 29400 | M30: =AVERAGE(M25:M29) -> 68000 | N30: =AVERAGE(N25:N29) -> 728 | O30: =AVERAGE(O25:O29) -> 59 | P30: =AVERAGE(P25:P29) -> 59
A31: I | B31: {} (add to {}) | C31: 0 | D31: =FACT(C31)*FACT(3-C31-1)/FACT(3) -> 0.33333333 | E31: =H14 -> 64.680743 | F31: =H11 -> 59 | G31: =E31-F31 -> 5.6807427 | H31: =D31*G31 -> 1.8935809
A32: I | B32: {L} (add to {L}) | C32: 1 | D32: =FACT(C32)*FACT(3-C32-1)/FACT(3) -> 0.16666667 | E32: =H16 -> 59.392448 | F32: =H13 -> 53.711705 | G32: =E32-F32 -> 5.6807427 | H32: =D32*G32 -> 0.94679044
A33: I | B33: {C} (add to {C}) | C33: 1 | D33: =FACT(C33)*FACT(3-C33-1)/FACT(3) -> 0.16666667 | E33: =H18 -> 37.115472 | F33: =H15 -> 31.434729 | G33: =E33-F33 -> 5.6807427 | H33: =D33*G33 -> 0.94679044
A34: I | B34: {L,C} (add to {L,C}) | C34: 2 | D34: =FACT(C34)*FACT(3-C34-1)/FACT(3) -> 0.33333333 | E34: =H19 -> 31.827177 | F34: =H17 -> 26.146434 | G34: =E34-F34 -> 5.6807427 | H34: =D34*G34 -> 1.8935809
H35: =SUM(H31:H34) -> 5.6807427
A36: phi_C =
A37: C | B37: {} (add to {}) | C37: 0 | D37: =FACT(C37)*FACT(3-C37-1)/FACT(3) -> 0.33333333 | E37: =H15 -> 31.434729 | F37: =H11 -> 59 | G37: =E37-F37 -> -27.565271 | H37: =D37*G37 -> -9.1884236
A38: C | B38: {L} (add to {L}) | C38: 1 | D38: =FACT(C38)*FACT(3-C38-1)/FACT(3) -> 0.16666667 | E38: =H17 -> 26.146434 | F38: =H13 -> 53.711705 | G38: =E38-F38 -> -27.565271 | H38: =D38*G38 -> -4.5942118
A39: C | B39: {I} (add to {I}) | C39: 1 | D39: =FACT(C39)*FACT(3-C39-1)/FACT(3) -> 0.16666667 | E39: =H18 -> 37.115472 | F39: =H14 -> 64.680743 | G39: =E39-F39 -> -27.565271 | H39: =D39*G39 -> -4.5942118
A40: C | B40: {L,I} (add to {L,I}) | C40: 2 | D40: =FACT(C40)*FACT(3-C40-1)/FACT(3) -> 0.33333333 | E40: =H19 -> 31.827177 | F40: =H16 -> 59.392448 | G40: =E40-F40 -> -27.565271 | H40: =D40*G40 -> -9.1884236
H41: =SUM(H37:H40) -> -27.565271

Sheet Sheet2
A1: Here's the full Shapley value calculation, done two ways so you can see the general method and confirm it against a closed-form check. | Q1: Good question — let me clarify the terminology, since two different things are both called "baseline-ish" in that sheet, and it's easy to mix them up.
A3: The Shapley formula (for feature i, out of feature set F): | Q3: Row 2 is not the baseline — it's the instance being explained.
A5: φᵢ = Σ over subsets S⊆F{i}: [|S|!·(|F|-|S|-1)!/|F|!] × [v(S∪{i}) − v(S)] | Q5: The instance = the specific applicant you want to explain: Row 2 (L=$15,000, I=$60,000, C=680, Approval=40%). I picked Row 2 somewhat arbitrarily as a worked example — nothing special about it except it has a noticeably low approval, so it's an interesting case to break down feature-by-feature.
Q6: The baseline (v(∅)) = the reference point used to represent "no information" — i.e., what the model predicts when none of the features are known. Since we don't have a real simulator to ask "what if we didn't know L,I,C," the standard trick is to plug in the average L, I, C across the whole dataset instead. That's the "Mean" row on the Dataset sheet — it's not Row 2, it's the average of all 5 rows.
A7: Here v(S) = the model's prediction when only the features in S are "known" and the rest are marginalized out (usually by averaging over the training/background data).
Q8: Why the two get combined in the v(S) table:
A9: Setup on your dataset:
Q10: Shapley values work by asking: "for every possible subset S of features that are 'known,' what does the model predict?" For features not in S, we don't get to leave them blank — a model needs a number for every feature — so we substitute the dataset mean as a stand-in for "unknown."
A11: Features: L, I, C → 3 features → 8 possible subsets (2³)
A12: I fit a quick linear model on your 5 rows to act as the black-box f(x), and used the dataset mean (L̄=29,400, Ī=68,000, C̄=728) as the baseline/missing-feature value. | Q12: So when you see, say, subset {L}: that row's v(S) uses Row 2's actual L=$15,000 (because L is "known" in that coalition) but the dataset mean for I and C (because they're "unknown" in that coalition). It's a blend of Row 2's real values (for included features) and dataset means (for excluded features) — never Row 2 acting as the baseline itself.
A13: Baseline v(∅) = model prediction at the mean = 59.0%
Q14: The full coalition {L,I,C} (last row of the table) uses Row 2's actual values for all three — that's how you recover the real model prediction, 31.83%, at one end. The empty coalition {} uses the mean for all three — that's the baseline, 59.0%, at the other end. Shapley values are just how you fairly split that 59.0% → 31.83% gap across L, I, and C.
A15: Worked example — Row 2 (L=15,000, I=60,000, C=680, actual=40%):
Q16: ok !
A17: I enumerated all 8 coalitions, computed the weighted marginal contribution of each feature across them, and got:
Q18: Sounds good — let me know if anything else comes up while you're going through it. 🙏
A19: Feature | B19: Shapley value φ
A20: L (Loan Amt) | B20: −5.29 | Q20: Want to be notified when Claude responds?
A21: I (Income) | B21: 5.68
A22: C (Credit Score) | B22: −27.57
A24: Check: 59.0 (baseline) + (−5.29 + 5.68 − 27.57) = 31.83%, matching the model's actual prediction for that row exactly. So the low credit score (680) is by far the biggest driver pulling this applicant's approval odds down.
A26: Shapley values for all 5 rows (baseline = 59.0):
A28: Row | B28: φ_L | C28: φ_I | D28: φ_C | E28: baseline+Σφ | F28: actual
A29: 1 | B29: −7.13 | C29: 16.33 | D29: −4.59 | E29: 63.61 | F29: 70
A30: 2 | B30: −5.29 | C30: 5.68 | D30: −27.57 | E30: 31.83 | F30: 40
A31: 3 | B31: 20.42 | C31: −12.07 | D31: 12.63 | E31: 79.98 | F31: 80
A32: 4 | B32: −6.39 | C32: 12.78 | D32: −21.82 | E32: 43.57 | F32: 30
A33: 5 | B33: −1.62 | C33: −22.72 | D33: 41.35 | E33: 76.01 | F33: 75
A35: Key property: in every row, baseline + φ_L + φ_I + φ_C = the model's prediction exactly — this "efficiency" property is what makes Shapley values additive and interpretable (each feature's φ is literally its fair share of the distance between the average prediction and this instance's prediction).
A37: For an actual black-box (Random Forest / Neural Net) instead of my quick linear stand-in, the formula is identical — you'd just replace v(S) with the real model's prediction after marginalizing the missing features (that's exactly what SHAP's TreeExplainer / KernelExplainer automate, since brute-forcing all 2ⁿ subsets gets expensive fast as feature count grows).
A39: Want me to redo this with an actual Random Forest trained on this data (or a larger synthetic version of it) so the numbers reflect a real black-box model rather than the linear stand-in?

Sheet Sheet3
A1: Harmless stray line, already saved fine before the error. Let me remove it and recalculate the workbook.
A3: Ran 4 commands, edited a file, read a file · 2 notes
A5: Four tabs, all live formulas (change any input and everything recalculates):
A7: 1. Dataset — your 5 rows plus the feature means (used as the "missing feature" baseline)
A8: 2. Model & Baseline — the linear model coefficients (blue = hardcoded input) and baseline v(∅)
A9: 3. Shapley Summary — φ_L, φ_I, φ_C for all 5 rows using the closed-form shortcut, with a check column proving baseline + Σφ = the model's prediction
A10: 4. Row2 Brute-Force Detail — the full manual method: all 8 feature coalitions, their v(S) values, then the weighted marginal-contribution table for each feature, ending in the same φ values as a cross-check
A12: In R, the main ones are:
A14: shapr – general-purpose Shapley value explanations for any predictive model, handles feature dependence well.
A15: iml (Interpretable Machine Learning) – has a Shapley class alongside other interpretability tools (PDP, ICE, etc.).
A16: fastshap – fast approximate Shapley values via Monte Carlo sampling.
A17: kernelshap – R implementation of the KernelSHAP method (model-agnostic, works well with DALEX/tidymodels).
... A39: Want me to add a polynomial-regression version to the Excel workbook, or is this for a separate exercise?

Sheet Shapley Summary
A1: Shapley Values — All Rows (closed form for a linear model: phi_i = b_i * (x_i - mean_i))
A3: Row | B3: L | C3: I | D3: C | E3: Actual Approval | F3: Model Pred f(x) | G3: phi_L | H3: phi_I | I3: phi_C | J3: Baseline+ sum(phi)
A4: =Dataset!A4 -> 1 | B4: =Dataset!B4 -> 10000 | C4: =Dataset!C4 -> 45000 | D4: =Dataset!D4 -> 720 | E4: =Dataset!F4 -> 70 | F4: ='Model & Baseline'!$B$5 + 'Model & Baseline'!$B$6*B4 + 'Model & Baseline'!$B$7*C4 + 'Model & Baseline'!$B$8*D4 -> 63.613415 | G4: ='Model & Baseline'!$B$6*(B4-Dataset!$B$9) -> -7.1245081 | H4: ='Model & Baseline'!$B$7*(C4-Dataset!$C$9) -> 16.332135 | I4: ='Model & Baseline'!$B$8*(D4-Dataset!$D$9) -> -4.5942118 | J4: ='Model & Baseline'!$D$15+G4+H4+I4 -> 63.613415
A5: =Dataset!A5 -> 2 | B5: =Dataset!B5 -> 15000 | C5: =Dataset!C5 -> 60000 | D5: =Dataset!D5 -> 680 | E5: =Dataset!F5 -> 40 | F5: ='Model & Baseline'!$B$5 + 'Model & Baseline'!$B$6*B5 + 'Model & Baseline'!$B$7*C5 + 'Model & Baseline'!$B$8*D5 -> 31.827177 | G5: ='Model & Baseline'!$B$6*(B5-Dataset!$B$9) -> -5.2882946 | H5: ='Model & Baseline'!$B$7*(C5-Dataset!$C$9) -> 5.6807427 | I5: ='Model & Baseline'!$B$8*(D5-Dataset!$D$9) -> -27.565271 | J5: ='Model & Baseline'!$D$15+G5+H5+I5 -> 31.827177
A6: =Dataset!A6 -> 3 | B6: =Dataset!B6 -> 85000 | C6: =Dataset!C6 -> 85000 | D6: =Dataset!D6 -> 750 | E6: =Dataset!F6 -> 80 | F6: ='Model & Baseline'!$B$5 + 'Model & Baseline'!$B$6*B6 + 'Model & Baseline'!$B$7*C6 + 'Model & Baseline'!$B$8*D6 -> 79.981197 | G6: ='Model & Baseline'!$B$6*(B6-Dataset!$B$9) -> 20.418693 | H6: ='Model & Baseline'!$B$7*(C6-Dataset!$C$9) -> -12.071578 | I6: ='Model & Baseline'!$B$8*(D6-Dataset!$D$9) -> 12.634082 | J6: ='Model & Baseline'!$D$15+G6+H6+I6 -> 79.981197
A7: =Dataset!A7 -> 4 | B7: =Dataset!B7 -> 12000 | C7: =Dataset!C7 -> 50000 | D7: =Dataset!D7 -> 690 | E7: =Dataset!F7 -> 30 | F7: ='Model & Baseline'!$B$5 + 'Model & Baseline'!$B$6*B7 + 'Model & Baseline'!$B$7*C7 + 'Model & Baseline'!$B$8*D7 -> 43.569142 | G7: ='Model & Baseline'!$B$6*(B7-Dataset!$B$9) -> -6.3900227 | H7: ='Model & Baseline'!$B$7*(C7-Dataset!$C$9) -> 12.781671 | I7: ='Model & Baseline'!$B$8*(D7-Dataset!$D$9) -> -21.822506 | J7: ='Model & Baseline'!$D$15+G7+H7+I7 -> 43.569142
A8: =Dataset!A8 -> 5 | B8: =Dataset!B8 -> 25000 | C8: =Dataset!C8 -> 100000 | D8: =Dataset!D8 -> 800 | E8: =Dataset!F8 -> 75 | F8: ='Model & Baseline'!$B$5 + 'Model & Baseline'!$B$6*B8 + 'Model & Baseline'!$B$7*C8 + 'Model & Baseline'!$B$8*D8 -> 76.009068 | G8: ='Model & Baseline'!$B$6*(B8-Dataset!$B$9) -> -1.6158678 | H8: ='Model & Baseline'!$B$7*(C8-Dataset!$C$9) -> -22.722971 | I8: ='Model & Baseline'!$B$8*(D8-Dataset!$D$9) -> 41.347906 | J8: ='Model & Baseline'!$D$15+G8+H8+I8 -> 76.009068
A10: Check column J should equal column F (Model Pred) for every row — this is the Shapley 'efficiency' property: baseline + sum of all feature contributions = the model's actual output.

Sheet Alternate_to_TREE
A1: !jupytext --to notebook E:\data_science\Udemy_Course_1\ | J1: IF U skip (MLE/log-likelihood & tree-based methods), alternative TO TREE BASED families:
A3: From PowerShell/Anaconda Prompt (recommended for a big batch) | J3: Distance/margin-based (no probability model at all)
A5: powershell | J5: k-Nearest Neighbors (KNN) — no training or optimization; classify by majority vote of nearest points. No likelihood involved.
J6: Support Vector Machine (SVM) — instead of maximizing likelihood, it maximizes the margin between classes; solved as a convex optimization (quadratic programming) minimizing hinge loss, not log-loss.
A7: cd E:\data_science\Udemy_Course_1 | J7: Perceptron — the original linear classifier; updates weights only when a point is misclassified (error-driven), no probability, no likelihood function at all.
A8: jupyter notebook | J8: Nearest Centroid Classifier — classify a point based on which class mean it's closest to.
A9: jupyter lab # if u want to open jupyter lab
A11: jupytext --to notebook *.py | D11: (it will open *.py file in the above path/directory | J11: Closed-form statistical (not iterative MLE)
A13: !jupytext --to notebook E:\data_science\Udemy_Course_1\scripts\*.py | J13: Linear Discriminant Analysis (LDA) — assumes each class is Gaussian-distributed and finds the linear boundary that best separates class means relative to within-class variance. Solved directly via means/covariance matrices (eigen-decomposition), not iterative gradient-based MLE like logistic regression.
J14: Least-squares classification — treat class labels (0/1) as a regression target and fit ordinary least squares directly; classify by thresholding the predicted value. (This is essentially what you were describing earlier — legitimate, just has known weaknesses versus logistic regression.)
A16: Option 3: Change the default notebook directory permanently | J16: Others worth knowing
A18: If you always want Jupyter to start on E:, edit the config: | J18: Naive Bayes — technically still uses probability/Bayes' theorem, but parameters are estimated by simple frequency counts, not iterative log-likelihood optimization.
J19: Neural network with hinge loss — same network architecture as logistic-loss networks, but swap the loss function to hinge loss (SVM-style) instead of cross-entropy.
A20: cmd
J21: If your exam is likely to test SVM and LDA specifically (very common pairing with logistic regression in DS curricula), those are the two I'd prioritize studying — they're the standard "alternative to logistic regression" answers in most textbooks and are conceptually distinct (margin-based vs. Gaussian-distribution-based) rather than variations on the same idea.
A22: jupyter notebook --generate-config
J23: Depends on which "equal distance" you mean — there are two different scenarios that come up:
A24: This creates jupyter_notebook_config.py
A25: (usually in C:\Users\<you>\.jupyter\). Open it and find/set: | J25: 1. Two training points equidistant from the hyperplane (tied as support vectors)
A27: python | J27: This isn't a problem at all — it's actually the normal, expected case. The max-margin hyperplane is found by solving a convex optimization (quadratic programming) that maximizes the margin width. It's totally common for multiple points from each class to land exactly on the margin boundary simultaneously — they all just become support vectors together. There's no "tie-break" needed; the optimizer doesn't pick one over the other, it finds the single unique hyperplane that satisfies the max-margin condition for all of them at once. In your image, if two red points both touch the left dashed margin line, both are support vectors — no conflict.
A28: c.NotebookApp.notebook_dir = 'E:/your/folder/path'
J29: 2. A test point sitting exactly ON the hyperplane itself (zero distance, truly ambiguous)
A31: Option 3: Change the default notebook directory permanently | J31: This is the genuinely ambiguous case — the point is equidistant from both classes, not just tied with another point. SVM's decision function is sign(w·x + b):
A33: If you always want Jupyter to start on E:, edit the config: | J33: distance > 0 → Class A
J34: distance < 0 → Class B
A35: cmd | J35: distance = 0 → undefined (sign(0) is typically just assigned to one class by convention, often the positive class)
A37: jupyter notebook --generate-config | J37: In practice this almost never happens exactly with real-valued continuous features — it's a measure-zero event. If it's a genuine concern for your use case (e.g., safety-critical decisions), the usual real-world handling isn't a "rule" but a different tool entirely:
A39: This creates jupyter_notebook_config.py (usually in C:\Users\<you>\.jupyter\). Open it and find/set: | J39: Platt scaling — calibrate SVM outputs into actual probabilities, so instead of a hard 0/1 call you get something like "51% vs 49%" and can flag it as low-confidence
J40: Reject option / abstention — if the point is within some ε of the hyperplane, decline to classify and route it for manual review instead of forcing a guess
A41: python
J42: So: ties among support vectors → not an issue, expected behavior. A test point exactly on the boundary → arbitrary convention, or better, treat it as low-confidence rather than force a hard call.
A43: c.NotebookApp.notebook_dir = 'E:/your/folder/path'
J44: What "margin" means: the perpendicular distance between the hyperplane and the nearest point(s) from either class — those nearest points are the support vectors. "Margin width" usually refers to the total gap between the two dashed lines in your image (one dashed line touching the nearest red point, the other touching the nearest grey point) — i.e., the width of the "no-man's-land" separating the classes.
A45: (uncomment the line, use forward slashes even on Windows). Save and restart Jupyter.
J46: The math: for hyperplane w·x + b = 0, the distance from any point x to it is |w·x+b| / ‖w‖. The two support vectors (one per class) sit at distance 1/‖w‖ from the hyperplane on each side (after scaling w,b so the closest points satisfy w·x+b = ±1). So:
J48: Margin (each side) = 1/‖w‖
A49: Quick tip: if you just need to read/write files from E:\ without changing directories, you can also just use the full path directly in your code, e.g. pd.read_csv(r'E:\data\file.csv'), without touching the working directory at all. | J49: Total margin width = 2/‖w‖
J51: Why this matters — it's the whole objective of SVM training: SVM doesn't just find any separating line — it specifically maximizes 2/‖w‖, which is the same as minimizing ‖w‖ (or equivalently ‖w‖², used in practice since it's smoother for optimization), subject to every point being correctly classified with at least that margin. That's the actual optimization problem being solved:
J53: minimize ½‖w‖² subject to yᵢ(w·xᵢ + b) ≥ 1 for all points i
J55: Why maximize the margin at all (intuition): a wider margin means the boundary sits as far as possible from both classes, which generally generalizes better to new/unseen points — a decision boundary squeezed tight against training points is more sensitive to noise and small perturbations.
...
